2019-10-09 19:33:41,879,8050,django.request,ERROR,exception.py:118,Internal Server Error: /api/user/login
Traceback (most recent call last):
  File "/usr/local/lib/python3.7/site-packages/rest_framework/views.py", line 502, in dispatch
    response = handler(request, *args, **kwargs)
  File "/Users/young/Desktop/python/Auto_Test_Platform/ApiTest/api/user.py", line 27, in post
    serializer.is_valid(raise_exception=True)
  File "/usr/local/lib/python3.7/site-packages/rest_framework/serializers.py", line 243, in is_valid
    raise ValidationError(self.errors)
rest_framework.exceptions.ValidationError: {'non_field_errors': [ErrorDetail(string='无法使用提供的认证信息登录。', code='authorization')]}

During handling of the above exception, another exception occurred:

Traceback (most recent call last):
  File "/usr/local/lib/python3.7/site-packages/rest_framework/settings.py", line 177, in import_from_string
    return import_string(val)
  File "/usr/local/lib/python3.7/site-packages/django/utils/module_loading.py", line 17, in import_string
    module = import_module(module_path)
  File "/usr/local/Cellar/python/3.7.0/Frameworks/Python.framework/Versions/3.7/lib/python3.7/importlib/__init__.py", line 127, in import_module
    return _bootstrap._gcd_import(name[level:], package, level)
  File "<frozen importlib._bootstrap>", line 1006, in _gcd_import
  File "<frozen importlib._bootstrap>", line 983, in _find_and_load
  File "<frozen importlib._bootstrap>", line 953, in _find_and_load_unlocked
  File "<frozen importlib._bootstrap>", line 219, in _call_with_frames_removed
  File "<frozen importlib._bootstrap>", line 1006, in _gcd_import
  File "<frozen importlib._bootstrap>", line 983, in _find_and_load
  File "<frozen importlib._bootstrap>", line 953, in _find_and_load_unlocked
  File "<frozen importlib._bootstrap>", line 219, in _call_with_frames_removed
  File "<frozen importlib._bootstrap>", line 1006, in _gcd_import
  File "<frozen importlib._bootstrap>", line 983, in _find_and_load
  File "<frozen importlib._bootstrap>", line 965, in _find_and_load_unlocked
ModuleNotFoundError: No module named 'api_test'

During handling of the above exception, another exception occurred:

Traceback (most recent call last):
  File "/usr/local/lib/python3.7/site-packages/django/core/handlers/exception.py", line 35, in inner
    response = get_response(request)
  File "/usr/local/lib/python3.7/site-packages/django/core/handlers/base.py", line 128, in _get_response
    response = self.process_exception_by_middleware(e, request)
  File "/usr/local/lib/python3.7/site-packages/django/core/handlers/base.py", line 126, in _get_response
    response = wrapped_callback(request, *callback_args, **callback_kwargs)
  File "/usr/local/lib/python3.7/site-packages/django/views/decorators/csrf.py", line 54, in wrapped_view
    return view_func(*args, **kwargs)
  File "/usr/local/lib/python3.7/site-packages/django/views/generic/base.py", line 69, in view
    return self.dispatch(request, *args, **kwargs)
  File "/usr/local/lib/python3.7/site-packages/rest_framework/views.py", line 505, in dispatch
    response = self.handle_exception(exc)
  File "/usr/local/lib/python3.7/site-packages/rest_framework/views.py", line 459, in handle_exception
    exception_handler = self.get_exception_handler()
  File "/usr/local/lib/python3.7/site-packages/rest_framework/views.py", line 298, in get_exception_handler
    return self.settings.EXCEPTION_HANDLER
  File "/usr/local/lib/python3.7/site-packages/rest_framework/settings.py", line 220, in __getattr__
    val = perform_import(val, attr)
  File "/usr/local/lib/python3.7/site-packages/rest_framework/settings.py", line 166, in perform_import
    return import_from_string(val, setting_name)
  File "/usr/local/lib/python3.7/site-packages/rest_framework/settings.py", line 180, in import_from_string
    raise ImportError(msg)
ImportError: Could not import 'api_test.common.common.custom_exception_handler' for API setting 'EXCEPTION_HANDLER'. ModuleNotFoundError: No module named 'api_test'.
2019-10-09 19:33:42,110,8050,django.server,ERROR,basehttp.py:124,"POST /api/user/login HTTP/1.1" 500 139844
2019-10-09 19:35:59,488,8105,django.request,ERROR,exception.py:118,Internal Server Error: /api/user/login
Traceback (most recent call last):
  File "/usr/local/lib/python3.7/site-packages/rest_framework/views.py", line 502, in dispatch
    response = handler(request, *args, **kwargs)
  File "/Users/young/Desktop/python/Auto_Test_Platform/ApiTest/api/user.py", line 27, in post
    serializer.is_valid(raise_exception=True)
  File "/usr/local/lib/python3.7/site-packages/rest_framework/serializers.py", line 243, in is_valid
    raise ValidationError(self.errors)
rest_framework.exceptions.ValidationError: {'non_field_errors': [ErrorDetail(string='无法使用提供的认证信息登录。', code='authorization')]}

During handling of the above exception, another exception occurred:

Traceback (most recent call last):
  File "/usr/local/lib/python3.7/site-packages/rest_framework/settings.py", line 177, in import_from_string
    return import_string(val)
  File "/usr/local/lib/python3.7/site-packages/django/utils/module_loading.py", line 17, in import_string
    module = import_module(module_path)
  File "/usr/local/Cellar/python/3.7.0/Frameworks/Python.framework/Versions/3.7/lib/python3.7/importlib/__init__.py", line 127, in import_module
    return _bootstrap._gcd_import(name[level:], package, level)
  File "<frozen importlib._bootstrap>", line 1006, in _gcd_import
  File "<frozen importlib._bootstrap>", line 983, in _find_and_load
  File "<frozen importlib._bootstrap>", line 953, in _find_and_load_unlocked
  File "<frozen importlib._bootstrap>", line 219, in _call_with_frames_removed
  File "<frozen importlib._bootstrap>", line 1006, in _gcd_import
  File "<frozen importlib._bootstrap>", line 983, in _find_and_load
  File "<frozen importlib._bootstrap>", line 953, in _find_and_load_unlocked
  File "<frozen importlib._bootstrap>", line 219, in _call_with_frames_removed
  File "<frozen importlib._bootstrap>", line 1006, in _gcd_import
  File "<frozen importlib._bootstrap>", line 983, in _find_and_load
  File "<frozen importlib._bootstrap>", line 965, in _find_and_load_unlocked
ModuleNotFoundError: No module named 'api_test'

During handling of the above exception, another exception occurred:

Traceback (most recent call last):
  File "/usr/local/lib/python3.7/site-packages/django/core/handlers/exception.py", line 35, in inner
    response = get_response(request)
  File "/usr/local/lib/python3.7/site-packages/django/core/handlers/base.py", line 128, in _get_response
    response = self.process_exception_by_middleware(e, request)
  File "/usr/local/lib/python3.7/site-packages/django/core/handlers/base.py", line 126, in _get_response
    response = wrapped_callback(request, *callback_args, **callback_kwargs)
  File "/usr/local/lib/python3.7/site-packages/django/views/decorators/csrf.py", line 54, in wrapped_view
    return view_func(*args, **kwargs)
  File "/usr/local/lib/python3.7/site-packages/django/views/generic/base.py", line 69, in view
    return self.dispatch(request, *args, **kwargs)
  File "/usr/local/lib/python3.7/site-packages/rest_framework/views.py", line 505, in dispatch
    response = self.handle_exception(exc)
  File "/usr/local/lib/python3.7/site-packages/rest_framework/views.py", line 459, in handle_exception
    exception_handler = self.get_exception_handler()
  File "/usr/local/lib/python3.7/site-packages/rest_framework/views.py", line 298, in get_exception_handler
    return self.settings.EXCEPTION_HANDLER
  File "/usr/local/lib/python3.7/site-packages/rest_framework/settings.py", line 220, in __getattr__
    val = perform_import(val, attr)
  File "/usr/local/lib/python3.7/site-packages/rest_framework/settings.py", line 166, in perform_import
    return import_from_string(val, setting_name)
  File "/usr/local/lib/python3.7/site-packages/rest_framework/settings.py", line 180, in import_from_string
    raise ImportError(msg)
ImportError: Could not import 'api_test.common.common.custom_exception_handler' for API setting 'EXCEPTION_HANDLER'. ModuleNotFoundError: No module named 'api_test'.
2019-10-09 19:35:59,597,8105,django.server,ERROR,basehttp.py:124,"POST /api/user/login HTTP/1.1" 500 139844
2019-10-09 19:37:48,539,8128,django.request,ERROR,exception.py:118,Internal Server Error: /api/user/login
Traceback (most recent call last):
  File "/usr/local/lib/python3.7/site-packages/rest_framework/views.py", line 502, in dispatch
    response = handler(request, *args, **kwargs)
  File "/Users/young/Desktop/python/Auto_Test_Platform/ApiTest/api/user.py", line 27, in post
    serializer.is_valid(raise_exception=True)
  File "/usr/local/lib/python3.7/site-packages/rest_framework/serializers.py", line 243, in is_valid
    raise ValidationError(self.errors)
rest_framework.exceptions.ValidationError: {'non_field_errors': [ErrorDetail(string='无法使用提供的认证信息登录。', code='authorization')]}

During handling of the above exception, another exception occurred:

Traceback (most recent call last):
  File "/usr/local/lib/python3.7/site-packages/rest_framework/settings.py", line 177, in import_from_string
    return import_string(val)
  File "/usr/local/lib/python3.7/site-packages/django/utils/module_loading.py", line 17, in import_string
    module = import_module(module_path)
  File "/usr/local/Cellar/python/3.7.0/Frameworks/Python.framework/Versions/3.7/lib/python3.7/importlib/__init__.py", line 127, in import_module
    return _bootstrap._gcd_import(name[level:], package, level)
  File "<frozen importlib._bootstrap>", line 1006, in _gcd_import
  File "<frozen importlib._bootstrap>", line 983, in _find_and_load
  File "<frozen importlib._bootstrap>", line 953, in _find_and_load_unlocked
  File "<frozen importlib._bootstrap>", line 219, in _call_with_frames_removed
  File "<frozen importlib._bootstrap>", line 1006, in _gcd_import
  File "<frozen importlib._bootstrap>", line 983, in _find_and_load
  File "<frozen importlib._bootstrap>", line 953, in _find_and_load_unlocked
  File "<frozen importlib._bootstrap>", line 219, in _call_with_frames_removed
  File "<frozen importlib._bootstrap>", line 1006, in _gcd_import
  File "<frozen importlib._bootstrap>", line 983, in _find_and_load
  File "<frozen importlib._bootstrap>", line 965, in _find_and_load_unlocked
ModuleNotFoundError: No module named 'api_test'

During handling of the above exception, another exception occurred:

Traceback (most recent call last):
  File "/usr/local/lib/python3.7/site-packages/django/core/handlers/exception.py", line 35, in inner
    response = get_response(request)
  File "/usr/local/lib/python3.7/site-packages/django/core/handlers/base.py", line 128, in _get_response
    response = self.process_exception_by_middleware(e, request)
  File "/usr/local/lib/python3.7/site-packages/django/core/handlers/base.py", line 126, in _get_response
    response = wrapped_callback(request, *callback_args, **callback_kwargs)
  File "/usr/local/lib/python3.7/site-packages/django/views/decorators/csrf.py", line 54, in wrapped_view
    return view_func(*args, **kwargs)
  File "/usr/local/lib/python3.7/site-packages/django/views/generic/base.py", line 69, in view
    return self.dispatch(request, *args, **kwargs)
  File "/usr/local/lib/python3.7/site-packages/rest_framework/views.py", line 505, in dispatch
    response = self.handle_exception(exc)
  File "/usr/local/lib/python3.7/site-packages/rest_framework/views.py", line 459, in handle_exception
    exception_handler = self.get_exception_handler()
  File "/usr/local/lib/python3.7/site-packages/rest_framework/views.py", line 298, in get_exception_handler
    return self.settings.EXCEPTION_HANDLER
  File "/usr/local/lib/python3.7/site-packages/rest_framework/settings.py", line 220, in __getattr__
    val = perform_import(val, attr)
  File "/usr/local/lib/python3.7/site-packages/rest_framework/settings.py", line 166, in perform_import
    return import_from_string(val, setting_name)
  File "/usr/local/lib/python3.7/site-packages/rest_framework/settings.py", line 180, in import_from_string
    raise ImportError(msg)
ImportError: Could not import 'api_test.common.common.custom_exception_handler' for API setting 'EXCEPTION_HANDLER'. ModuleNotFoundError: No module named 'api_test'.
2019-10-09 19:37:48,645,8128,django.server,ERROR,basehttp.py:124,"POST /api/user/login HTTP/1.1" 500 139844
